Workbook

Sheet Dashboard
H2: REVENUE | I2: : | J2: =AVERAGE(RAW_Data!J:J) -> 3029.59 | O2: BEST MANAGER | P2: : | Q2: =Analysis!D25 -> Joao Silva | V2: BEST PRODUCT | W2: : | X2: =Analysis!A13 -> Beverages
V31: Total Income
O39: Total Income | P39: : | Q39: =GETPIVOTDATA("Revenue",$E$88) -> 437401.2 | V39: Total Transaction | W39: : | X39: =_xlfn.CONCAT(GETPIVOTDATA("Order ID",$E$120)," Order") -> 141 Order
B70: CHART DATA
B71: Manager | E71: Payment | H71: Product Performance
B72: =Analysis!D25 -> Joao Silva | C72: =Analysis!E25 -> 16074.435 | E72: =Analysis!A3 -> Credit Card | F72: =Analysis!B3 -> 120 | H72: {=Analysis!A13:B18} -> Beverages | I72: 34983.14
B73: =Analysis!D26 -> Walter Muller | C73: =Analysis!E26 -> 9800.0457 | E73: =Analysis!A4 -> Cash | F73: =Analysis!B4 -> 76 | H73: Fries | I73: 32034.34
B74: =Analysis!D27 -> Tom Jackson | C74: =Analysis!E27 -> 7600.0593 | E74: =Analysis!A5 -> Gift Card | F74: =Analysis!B5 -> 58 | H74: Burgers | I74: 29022.31
B75: =Analysis!D28 -> Pablo Perez | C75: =Analysis!E28 -> 7199.9673 | E75: =Analysis!A6 -> Grand Total | F75: =Analysis!B6 -> 254 | H75: Chicken Sandwiches | I75: 11135.92
B76: =Analysis!D29 -> Remy Monet | C76: =Analysis!E29 -> 7199.9673 | H76: Sides & Other | I76: 9819.6
B77: =Analysis!D30 -> Grand Total | C77: =Analysis!E30 -> 16074.435 | H77: Grand Total | I77: 116995.31
B79: Revenue per Day | E79: Revenue by City | H79: Row Labels | I79: Count of Order ID
B80: =Analysis!A36 -> 44872 | C80: =Analysis!B36 -> 5200.0023 | E80: {=Analysis!A25:B30} -> Lisbon | F80: 16074.435 | H80: Drive-thru | I80: 61
B81: =Analysis!A37 -> 44873 | C81: =Analysis!B37 -> 12400.073 | E81: Berlin | F81: 9800.0457 | H81: In-store | I81: 86
B82: =Analysis!A38 -> 44874 | C82: =Analysis!B38 -> 14200.039 | E82: London | F82: 7600.0593 | H82: Online | I82: 107
B83: =Analysis!A39 -> 44875 | C83: =Analysis!B39 -> 13200.043 | E83: Madrid | F83: 7199.9673 | H83: Grand Total | I83: 254
B84: =Analysis!A40 -> 44876 | C84: =Analysis!B40 -> 14400.016 | E84: Paris | F84: 7199.9673
B85: =Analysis!A41 -> 44877 | C85: =Analysis!B41 -> 14000.054 | E85: Grand Total | F85: 16074.435
B86: =Analysis!A42 -> 44878 | C86: =Analysis!B42 -> 27674.451
B87: =Analysis!A43 -> 44879 | C87: =Analysis!B43 -> 17839.344 | E87: Total Income
B88: =Analysis!A44 -> 44880 | C88: =Analysis!B44 -> 13600.031 | E88: Row Labels | F88: Sum of Revenue
B89: =Analysis!A45 -> 44881 | C89: =Analysis!B45 -> 13600.031 | E89: 44896 | F89: 13400.114
B90: =Analysis!A46 -> 44882 | C90: =Analysis!B46 -> 14000.054 | E90: 44897 | F90: 14000.054
B91: =Analysis!A47 -> 44883 | C91: =Analysis!B47 -> 14400.111 | E91: 44898 | F91: 14000.054
B92: =Analysis!A48 -> 44884 | C92: =Analysis!B48 -> 14000.019 | E92: 44899 | F92: 9000.1007
B93: =Analysis!A49 -> 44885 | C93: =Analysis!B49 -> 8200.0466 | E93: 44900 | F93: 14200.039
B94: =Analysis!A50 -> 44886 | C94: =Analysis!B50 -> 14000.084 | E94: 44901 | F94: 14000.123
B95: =Analysis!A51 -> 44887 | C95: =Analysis!B51 -> 13599.992 | E95: 44902 | F95: 14000.054
B96: =Analysis!A52 -> 44888 | C96: =Analysis!B52 -> 13800.038 | E96: 44903 | F96: 14200.1
B97: =Analysis!A53 -> 44889 | C97: =Analysis!B53 -> 13600.026 | E97: 44904 | F97: 14600.062
B98: =Analysis!A54 -> 44890 | C98: =Analysis!B54 -> 13399.98 | E98: 44905 | F98: 14600.062
B99: =Analysis!A55 -> 44891 | C99: =Analysis!B55 -> 13200.064 | E99: 44906 | F99: 15000.088
B100: =Analysis!A56 -> 44892 | C100: =Analysis!B56 -> 13399.98 | E100: 44907 | F100: 14600.062
... B117: =Analysis!A73 -> 44909 | C117: =Analysis!B73 -> 14600.011 | E117: 44924 | F117: 16800.078
B118: =Analysis!A74 -> 44910 | C118: =Analysis!B74 -> 14400.094 | E118: Grand Total | F118: 437401.2
B119: =Analysis!A75 -> 44911 | C119: =Analysis!B75 -> 15000.037
B120: =Analysis!A76 -> 44912 | C120: =Analysis!B76 -> 15400.095 | E120: Row Labels | F120: Count of Order ID
B121: =Analysis!A77 -> 44913 | C121: =Analysis!B77 -> 15600.011 | E121: 44896 | F121: 5
B122: =Analysis!A78 -> 44914 | C122: =Analysis!B78 -> 15799.961 | E122: 44897 | F122: 5
B123: =Analysis!A79 -> 44915 | C123: =Analysis!B79 -> 16000.007 | E123: 44898 | F123: 5
...

Sheet Analysis
A1: Q1 : Most Preferred Payment Method? | K1: Q5 : Average Revenue.
A2: Row Labels | B2: Count of Order ID | K2: Average of Revenue
A3: Credit Card | B3: 120 | K3: 3029.59
A4: Cash | B4: 76
A5: Gift Card | B5: 58 | K5: Insight : Average revenue of the restaurant is 3029.589997
A6: Grand Total | B6: 254
K7: Q6 : Average Revenue of November & December month.
K8: Row Labels | L8: Average of Revenue | N8: Row Labels | O8: Average of Revenue
A9: Insight: Credit Card is the most preferred payment method with the highest number of transactions. | K9: 44872 | L9: 1733.3341 | N9: 44896 | O9: 2680.0229
K10: 44873 | L10: 3100.0183 | N10: 44897 | O10: 2800.0107
A11: Q2 : Most Selling Product - By Quantity & By Revenue? | K11: 44874 | L11: 2840.0077 | N11: 44898 | O11: 2800.0107
A12: Row Labels | B12: Sum of Quantity | D12: Row Labels | E12: Sum of Revenue | K12: 44875 | L12: 3300.0107 | N12: 44899 | O12: 4500.0503
A13: Beverages | B13: 34983.14 | D13: Burgers | E13: 376999.81 | K13: 44876 | L13: 2880.0031 | N13: 44900 | O13: 2840.0077
A14: Fries | B14: 32034.34 | D14: Fries | E14: 125674.29 | K14: 44877 | L14: 2800.0107 | N14: 44901 | O14: 2800.0245
A15: Burgers | B15: 29022.31 | D15: Chicken Sandwiches | E15: 114641.7 | K15: 44878 | L15: 5534.8902 | N15: 44902 | O15: 2800.0107
A16: Chicken Sandwiches | B16: 11135.92 | D16: Beverages | E16: 103200.26 | K16: 44879 | L16: 3567.8689 | N16: 44903 | O16: 2840.0199
A17: Sides & Other | B17: 9819.6 | D17: Sides & Other | E17: 48999.804 | K17: 44880 | L17: 2720.0061 | N17: 44904 | O17: 2920.0123
A18: Grand Total | B18: 116995.31 | D18: Grand Total | E18: 769515.86 | K18: 44881 | L18: 2720.0061 | N18: 44905 | O18: 2920.0123
K19: 44882 | L19: 2800.0107 | N19: 44906 | O19: 3000.0176
K20: 44883 | L20: 2880.0223 | N20: 44907 | O20: 2920.0123
A21: Insight : Beverages has the highest quantity sold, otherwise Burgers generates the highest product revenue. | K21: 44884 | L21: 2800.0039 | N21: 44908 | O21: 2920.0123
K22: 44885 | L22: 4100.0233 | N22: 44909 | O22: 2920.0021
A23: Q3 : Which city had maximum revenue , or , Which Manager earned maximum revenue? | K23: 44886 | L23: 2800.0168 | N23: 44910 | O23: 2880.0189
A24: Row Labels | B24: Max of Revenue | D24: Row Labels | E24: Max of Revenue | K24: 44887 | L24: 2719.9984 | N24: 44911 | O24: 3000.0074
A25: Lisbon | B25: 16074.435 | D25: Joao Silva | E25: 16074.435 | K25: 44888 | L25: 2760.0076 | N25: 44912 | O25: 3080.019
A26: Berlin | B26: 9800.0457 | D26: Walter Muller | E26: 9800.0457 | K26: 44889 | L26: 2720.0052 | N26: 44913 | O26: 3120.0022
A27: London | B27: 7600.0593 | D27: Tom Jackson | E27: 7600.0593 | K27: 44890 | L27: 2679.996 | N27: 44914 | O27: 3159.9923
A28: Madrid | B28: 7199.9673 | D28: Pablo Perez | E28: 7199.9673 | K28: 44891 | L28: 2640.0128 | N28: 44915 | O28: 3200.0015
A29: Paris | B29: 7199.9673 | D29: Remy Monet | E29: 7199.9673 | K29: 44892 | L29: 2679.996 | N29: 44916 | O29: 3279.9939
A30: Grand Total | B30: 16074.435 | D30: Grand Total | E30: 16074.435 | K30: 44893 | L30: 2680.0091 | N30: 44917 | O30: 3319.9929
K31: 44894 | L31: 2680.0091 | N31: 44918 | O31: 3200.0044
A32: Insight : Lisbon and Joao Silva get the highest revenue | K32: 44895 | L32: 2720.0183 | N32: 44919 | O32: 3279.9968
K33: Grand Total | L33: 2939.0678 | N33: 44920 | O33: 3319.9958
A34: Q4 : Date wise revenue. | N34: 44921 | O34: 3400.004
A35: Row Labels | B35: Sum of Revenue | N35: 44922 | O35: 3400.004
A36: 44872 | B36: 5200.0023 | N36: 44923 | O36: 3519.9954
A37: 44873 | B37: 12400.073 | N37: 44924 | O37: 4200.0195
A38: 44874 | B38: 14200.039 | N38: Grand Total | O38: 3102.1362
A39: 44875 | B39: 13200.043
A40: 44876 | B40: 14400.016 | K40: Insight : Average revenue on November is 2939.06 and December is 3102.13
...

Sheet RAW_Data
A1: Order ID | B1: Date | C1: Product | D1: Price | E1: Quantity | F1: Purchase Type | G1: Payment Method | H1: Manager | I1: City | J1: Revenue | K1: Manager(Clean)
A2: 10452 | B2: 44872 | C2: Fries | D2: 3.49 | E2: 573.07 | F2: Online | G2: Gift Card | H2: Tom Jackson | I2: London | J2: =D2*E2 -> 2000.0143 | K2: =TRIM(H2) -> Tom Jackson
A3: 10453 | B3: 44872 | C3: Beverages | D3: 2.95 | E3: 745.76 | F3: Online | G3: Gift Card | H3: Pablo Perez | I3: Madrid | J3: =D3*E3 -> 2199.992 | K3: =TRIM(H3) -> Pablo Perez
A4: 10454 | B4: 44872 | C4: Sides & Other | D4: 4.99 | E4: 200.4 | F4: In-store | G4: Gift Card | H4: Joao Silva | I4: Lisbon | J4: =D4*E4 -> 999.996 | K4: =TRIM(H4) -> Joao Silva
A5: 10455 | B5: 44873 | C5: Burgers | D5: 12.99 | E5: 569.67 | F5: In-store | G5: Credit Card | H5: Walter Muller | I5: Berlin | J5: =D5*E5 -> 7400.0133 | K5: =TRIM(H5) -> Walter Muller
A6: 10456 | B6: 44873 | C6: Chicken Sandwiches | D6: 9.95 | E6: 201.01 | F6: In-store | G6: Credit Card | H6: Walter Muller | I6: Berlin | J6: =D6*E6 -> 2000.0495 | K6: =TRIM(H6) -> Walter Muller
A7: 10457 | B7: 44873 | C7: Fries | D7: 3.49 | E7: 573.07 | F7: In-store | G7: Credit Card | H7: Remy Monet | I7: Paris | J7: =D7*E7 -> 2000.0143 | K7: =TRIM(H7) -> Remy Monet
A8: 10459 | B8: 44873 | C8: Sides & Other | D8: 4.99 | E8: 200.4 | F8: In-store | G8: Credit Card | H8: Walter Muller | I8: Berlin | J8: =D8*E8 -> 999.996 | K8: =TRIM(H8) -> Walter Muller
A9: 10460 | B9: 44874 | C9: Burgers | D9: 12.99 | E9: 554.27 | F9: In-store | G9: Credit Card | H9: Remy Monet | I9: Paris | J9: =D9*E9 -> 7199.9673 | K9: =TRIM(H9) -> Remy Monet
A10: 10461 | B10: 44874 | C10: Chicken Sandwiches | D10: 9.95 | E10: 201.01 | F10: In-store | G10: Credit Card | H10: Remy Monet | I10: Paris | J10: =D10*E10 -> 2000.0495 | K10: =TRIM(H10) -> Remy Monet
A11: 10462 | B11: 44874 | C11: Fries | D11: 3.49 | E11: 573.07 | F11: In-store | G11: Credit Card | H11: Remy Monet | I11: Paris | J11: =D11*E11 -> 2000.0143 | K11: =TRIM(H11) -> Remy Monet
A12: 10463 | B12: 44874 | C12: Beverages | D12: 2.95 | E12: 677.97 | F12: In-store | G12: Credit Card | H12: Remy Monet | I12: Paris | J12: =D12*E12 -> 2000.0115 | K12: =TRIM(H12) -> Remy Monet
A13: 10464 | B13: 44874 | C13: Sides & Other | D13: 4.99 | E13: 200.4 | F13: In-store | G13: Credit Card | H13: Remy Monet | I13: Paris | J13: =D13*E13 -> 999.996 | K13: =TRIM(H13) -> Remy Monet
... A255: 10713 | B255: 44924 | C255: Beverages | D255: 2.95 | E255: 677.97 | F255: Drive-thru | G255: Gift Card | H255: Walter Muller | I255: Berlin | J255: =D255*E255 -> 2000.0115 | K255: =TRIM(H255) -> Walter Muller
